<?xml version='1.0'?>
<robot name="full_robot" xmlns:xacro="http://www.ros.org/wiki/xacro">
    <xacro:include filename="$(find hummanoid)/urdf/hum_robot_info.gazebo" />

    <link name="base_footprint" />

    <link name="base_link">
      <pose>0 0 0.1 0 0 0</pose>
  
      <inertial>
        <mass value="10" />
        <origin xyz="0 0 0.1" rpy="0 0 0" />
        <inertia ixx="0.1" iyy="0.1" izz="0.1" ixy="0.0" ixz="0.0" iyz="0.0" />
      </inertial>
  
      <visual name='base_visual'>
        <geometry>
          <box size="0.984 0.65 0.095" />
        </geometry>
        <origin rpy="0 0 0" xyz="0 0 0" /><!--.125-->
      </visual>
      <collision name='base_collision'>
        <geometry>
          <box size="0.984 0.65 0.095" />
        </geometry>
      </collision>
  
  
  
  
      <collision name='lidar_bed'>
        <origin xyz="0.4 0.0 0.05" rpy="0.0 0.0 0.0" />
        <geometry>
          <box size="0.1 0.1 0.1" />
        </geometry>
      </collision>
      <visual name='lidar_bed_visual'>
        <origin xyz="0.4 0.0 0.05" rpy="0.0 0.0 0.0" />
        <geometry>
          <box size="0.1 0.1 0.1" />
        </geometry>
      </visual>
  
    </link>
  
    <link name="caster_right">
    <collision name="caster_wheel_right_collision">
      <origin rpy="0 0 0" xyz="0 0 0" />
      <geometry>
        <sphere radius="0.07" />
      </geometry>
    </collision>
    <visual name="caster_wheel_right_visual">
      <origin rpy="0 0 0" xyz="0 0 0" />
      <geometry>
        <sphere radius="0.07" />
      </geometry>
    </visual>
  </link>
  

  
  <link name="caster_left">
    <collision name="caster_wheel_left_collision">
      <origin rpy="0 0 0" xyz="0 0 0" />
      <geometry>
        <sphere radius="0.07" />
      </geometry>
    </collision>
  
    <visual name="caster_wheel_left_visual">
      <origin rpy="0 0 0" xyz="0 0 0" />
      <geometry>
        <sphere radius="0.07" />
      </geometry>
    </visual>
  </link>
  

  
  <joint name="caster_right_joint" type="fixed">
    <parent link="base_link" />
    <child link="caster_right" />
    <axis xyz="0 1 0" />
    <origin xyz="0.367135 0.2 -0.05" />
  </joint>
  
  
  <joint name="caster_left_joint" type="fixed">
    <parent link="base_link" />
    <child link="caster_left" />
    <axis xyz="0 1 0" />
    <origin xyz="0.367135 -0.2 -0.05" />
  </joint>
  
    <link name="laser_frame">
      <visual>
        <geometry>
          <cylinder radius="0.05" length="0.04" />
        </geometry>
      </visual>
      <collision>
        <geometry>
          <cylinder radius="0.05" length="0.04" />
        </geometry>
      </collision>
      <inertial>
        <mass value="0.5" />
        <origin xyz="0 0 0" rpy="0 0 0" />
        <inertia ixx="0.03" iyy="0.03" izz="0.03" ixy="0.0" ixz="0.0" iyz="0.0" />
      </inertial>
    </link>
  
    <joint name='laser_frame_to_base_link' type='fixed'>
      <parent link="base_link" />
      <child link="laser_frame" />
      <origin xyz="0.4 0.0 0.114" rpy="0.0 0.0 0.0" />
      <axis xyz="0 0 1" />
  
    </joint>


    <joint name="base_footprint_to_base_link" type="fixed">
        <parent link="base_footprint" />
        <child link="base_link" />
        <origin rpy="0 0 0" xyz="0 0 0" /><!--0.492135
        0 0/-->
      </joint>
    
    
      <link name="right_wheel">
        <visual name="right_wheel_visual">
          <geometry>
            <cylinder length="0.065" radius="0.125" />
          </geometry>
          <origin rpy="0 1.5707 1.5707" xyz="0 0 0" />
        </visual>
        <collision>
          <origin rpy="0 1.5707 1.5707" xyz="0 0 0" />
          <geometry>
            <cylinder length="0.065" radius="0.125" />
          </geometry>
        </collision>
        <inertial>
          <mass value="1" />
          <origin xyz="0 0 0" rpy="0 1.5707 1.5707" />
          <inertia ixx="0.1" iyy="0.1" izz="0.1" ixy="0.0" ixz="0.0" iyz="0.0" />
        </inertial>
      </link>
    
      <link name="left_wheel">
        <visual>
          <geometry>
            <cylinder length="0.065" radius="0.125" />
          </geometry>
          <origin rpy="0 1.5707 1.5707" xyz="0 0 0" />
        </visual>
        <collision>
          <origin rpy="0 1.5707 1.5707" xyz="0 0 0" />
          <geometry>
            <cylinder length="0.065" radius="0.125" />
          </geometry>
        </collision>
        <inertial>
          <mass value="1" />
          <origin xyz="0 0 0" rpy="0 0 0" />
          <inertia ixx="0.1" iyy="0.1" izz="0.1" ixy="0.0" ixz="0.0" iyz="0.0" />
        </inertial>
      </link>
    
    
      <joint name="wheel_0_joint" type="continuous">
        <parent link="base_link" />
        <child link="right_wheel" />
        <axis xyz="0 1 0" />
        <origin xyz="-0.315 0.355 0.0" />
      </joint>
    
    
      <joint name="wheel_1_joint" type="continuous">
        <parent link="base_link" />
        <child link="left_wheel" />
        <axis xyz="0 1 0" />
        <origin xyz="-0.315 -0.355 0.0" />
      </joint>
    
    
      <link name="kinect_link">
        <visual>
          <geometry>
            <box size="0.064 0.121 0.0381" />
          </geometry>
        </visual>
        <collision>
          <geometry>
            <box size="0.064 0.121 0.0381" />
          </geometry>
          <material name="Black" />
        </collision>
        <inertial>
          <mass value="0.0001" />
          <origin xyz="0 0 0" />
          <inertia ixx="0.0001" ixy="0.0" ixz="0.0"
            iyy="0.0001" iyz="0.0"
            izz="0.0001" />
        </inertial>
      </link>
    
    
      <joint name="kinect_depth_joint" type="fixed">
        <origin xyz="0 0.028 0" rpy="0 0 0" />
        <parent link="kinect_link" />
        <child link="kinect_depth_frame" />
      </joint>
    
      <link name="kinect_depth_frame">
        <inertial>
          <mass value="0.0001" />
          <origin xyz="0 0 0" />
          <inertia ixx="0.0001" ixy="0.0" ixz="0.0"
            iyy="0.0001" iyz="0.0"
            izz="0.0001" />
        </inertial>
      </link>
    
      <joint name="depth_optical_joint" type="fixed">
        <origin xyz="0 0 0" rpy="0 0 0" />
        <parent link="kinect_depth_frame" />
        <child link="kinect_depth_optical_frame" />
      </joint>
    
      <link name="kinect_depth_optical_frame">
        <inertial>
          <mass value="0.0001" />
          <origin xyz="0 0 0" />
          <inertia ixx="0.0001" ixy="0.0" ixz="0.0"
            iyy="0.0001" iyz="0.0"
            izz="0.0001" />
        </inertial>
      </link>
    
      <joint name="base_link_to_kinect_link" type="fixed">
        <parent link="base_link" />
        <child link="kinect_link" />
        <origin rpy="0 0 0" xyz="0.5 0 0.05155" /><!--0.4-->
      </joint>
    
    
      <link name="leg1">
        <visual>
          <origin rpy="0 0 0" xyz="0 0 0" />
          <geometry>
            <cylinder radius="0.125" length="0.6" />
          </geometry>
        </visual>
        <collision>
          <origin rpy="0 0 0" xyz="0 0 0" />
          <geometry>
            <cylinder radius="0.125" length="0.6" />
          </geometry>
        </collision>
        <inertial>
          <mass value="5" />
          <origin xyz="0 0 0" rpy="0 0 0" />
          <inertia ixx="0.03" iyy="0.03" izz="0.03" ixy="0.0" ixz="0.0" iyz="0.0" />
        </inertial>
      </link>
      <link name="leg2">
        <visual>
          <origin rpy="0 0 0" xyz="0 0 0" />
          <geometry>
            <cylinder radius="0.125" length="0.6" />
          </geometry>
        </visual>
        <collision>
          <origin rpy="0 0 0" xyz="0 0 0" />
          <geometry>
            <cylinder radius="0.125" length="0.6" />
          </geometry>
          <color rgba="0 0 1 1" />
        </collision>
        <inertial>
          <mass value="5" />
          <origin xyz="0 0 0" rpy="0 0 0" />
          <inertia ixx="0.03" iyy="0.03" izz="0.03" ixy="0.0" ixz="0.0" iyz="0.0" />
        </inertial>
      </link>
    
      <joint name="base_link_leg1" type="fixed">
        <origin xyz="0.09375 0.105 0.35" rpy="0 0 0" />
        <parent link="base_link" />
        <child link="leg1" />
        <limit effort="30" velocity="1.0" lower="-1.57" upper="1.57" />
        <axis xyz="0 0 1" />
      </joint>
      <joint name="base_link_leg2" type="fixed">
        <origin xyz="0.09375 -0.105 0.35" rpy="0 0 0" />
        <parent link="base_link" />
        <child link="leg2" />
        <limit effort="30" velocity="1.0" lower="-1.57" upper="1.57" />
        <axis xyz="0 0 1" />
      </joint>




</robot>