<?xml version="1.0" encoding="UTF-8"?>
<robot name="full_robot">
    <material name="Blue">
    <color rgba="0 0 0.8 1"/>
  </material>
  <material name="Black">
    <color rgba="0 0 0 1"/>
  </material>
  <material name="White">
    <color rgba="1 1 1 1"/>
  </material>



<link name="base_footprint" />
  
  <link name="base_link">
    <visual>
      <geometry>
        <box size="0.984 0.65 0.095"/>
      </geometry>
      <origin rpy="0 0 0" xyz="0 0 0.125"/><!--.125-->
      <material name="Blue"/>
    </visual>
    <collision>
      <origin rpy="0 3.14 0" xyz="0 0 0"/>
       <geometry>
          <box size="0.984 0.65 0.095"/>
        </geometry>
       </collision>
        <inertial>
            <mass value="0.1" />
            <origin xyz="0 0 0" rpy="0 0 0" />
            <inertia ixx="0.03" iyy="0.03" izz="0.03" ixy="0.0" ixz="0.0" iyz="0.0" />
        </inertial>
  </link>
  
  <joint name="base_footprint_to_base_link" type="fixed">
    <parent link="base_footprint"/>
    <child link="base_link"/>
    <origin rpy="0 0 0" xyz="0 0 0"/><!--0.492135 0 0/-->
  </joint>



  <link name="right_wheel">
    <visual>
      <geometry>
        <cylinder length="0.065" radius="0.125"/>
      </geometry>
      <origin rpy="1.5707 0 0" xyz="0 0 0"/>
      <material name="Black"/>
    </visual>
    <collision>
      <geometry>
        <cylinder length="0.065" radius="0.125"/>
      </geometry>
    </collision>
    <inertial>
       <mass value="0.1" />
       <origin xyz="0 0 0" rpy="0 0 0" />
       <inertia ixx="0.03" iyy="0.03" izz="0.03" ixy="0.0" ixz="0.0" iyz="0.0" />
    </inertial>
  </link>
  
  <link name="left_wheel">
    <visual>
      <geometry>
        <cylinder length="0.065" radius="0.125"/>
      </geometry>
      <origin rpy="1.5707 0 0" xyz="0 0 0"/>
      <material name="Black"/>
    </visual>
    <collision>
      <geometry>
        <cylinder length="0.065" radius="0.125"/>
      </geometry>
    </collision>
    <inertial>
       <mass value="0.1" />
       <origin xyz="0 0 0" rpy="0 0 0" />
       <inertia ixx="0.03" iyy="0.03" izz="0.03" ixy="0.0" ixz="0.0" iyz="0.0" />
    </inertial>
  </link>
  
  <link name="caster_wheel_right">
    <visual>
      <origin rpy="0 0 0" xyz="0 0 0" />
            <geometry>
                <sphere radius="0.08" />
            </geometry>
            <material name="blue">
                <color rgba="0 0 1 1" />
            </material>
        </visual>
        <collision>
            <origin rpy="0 0 0" xyz="0 0 0" />
            <geometry>
                <sphere radius="0.08" />
            </geometry>
            <material name="blue" />
            <color rgba="0 0 1 1" />
        </collision>
        <inertial>
            <mass value="0.1" />
            <origin xyz="0 0 0" rpy="0 0 0" />
            <inertia ixx="0.03" iyy="0.03" izz="0.03" ixy="0.0" ixz="0.0" iyz="0.0" />
        </inertial>
  </link>
  
    <link name="caster_wheel_left">
    <visual>
      <origin rpy="0 0 0" xyz="0 0 0" />
            <geometry>
                <sphere radius="0.08" />
            </geometry>
            <material name="blue">
                <color rgba="0 0 1 1" />
            </material>
        </visual>
        <collision>
            <origin rpy="0 0 0" xyz="0 0 0" />
            <geometry>
                <sphere radius="0.08" />
            </geometry>
            <material name="blue" />
            <color rgba="0 0 1 1" />
        </collision>
        <inertial>
            <mass value="0.1" />
            <origin xyz="0 0 0" rpy="0 0 0" />
            <inertia ixx="0.03" iyy="0.03" izz="0.03" ixy="0.0" ixz="0.0" iyz="0.0" />
        </inertial>

  </link>
  


  
  
  <joint name="wheel_0_joint" type="continuous">
    <parent link="base_link"/>
    <child link="right_wheel"/>
    <axis xyz="0 -1 0"/>
    <origin xyz="-0.315 0.355 0.12"/>
  </joint>

  

  <joint name="wheel_1_joint" type="continuous">
    <parent link="base_link"/>
    <child link="left_wheel"/>
    <axis xyz="0 -1 0"/>
    <origin xyz="-0.315 -0.355 0.12"/>
  </joint>

  

  <joint name="base_link_to_caster_wheel_right" type="continuous">
    <parent link="base_link"/>
    <child link="caster_wheel_right"/>
    <axis xyz="0 0 0"/>
    <origin rpy="0 0 0" xyz="0.367135 0.2 0"/>
  </joint>



  <joint name="base_link_to_caster_wheel_left" type="continuous">
    <parent link="base_link"/>
    <child link="caster_wheel_left"/>
    <axis xyz="1 1 1"/>
    <origin rpy="0 0 0" xyz="0.367135 -0.2 0.0"/>
  </joint>

  
  <link name="kinect_link">
  <visual>
    <geometry>
      <box size="0.064 0.121 0.0381" />
    </geometry>
    <material name="Black" />
  </visual>
  <collision>
    <geometry>
      <box size="0.064 0.121 0.0381" />
    </geometry>
    <material name="Black" />
  </collision>
   <inertial>
      <mass value="0.0001" />
      <origin xyz="0 0 0" />
      <inertia ixx="0.0001" ixy="0.0" ixz="0.0"
               iyy="0.0001" iyz="0.0" 
               izz="0.0001" />
  </inertial>
</link>


<joint name="kinect_depth_joint" type="fixed">
  <origin xyz="0 0.028 0" rpy="0 0 0" />
  <parent link="kinect_link" />
  <child link="kinect_depth_frame" />
</joint>

<link name="kinect_depth_frame">
  <inertial>
      <mass value="0.0001" />
      <origin xyz="0 0 0" />
      <inertia ixx="0.0001" ixy="0.0" ixz="0.0"
               iyy="0.0001" iyz="0.0" 
               izz="0.0001" />
  </inertial>
</link>

<joint name="depth_optical_joint" type="fixed">
  <origin xyz="0 0 0" rpy="0 0 0" />
  <parent link="kinect_depth_frame" />
  <child link="kinect_depth_optical_frame" />
</joint>

<link name="kinect_depth_optical_frame">
  <inertial>
      <mass value="0.0001" />
      <origin xyz="0 0 0" />
      <inertia ixx="0.0001" ixy="0.0" ixz="0.0"
               iyy="0.0001" iyz="0.0" 
               izz="0.0001" />
  </inertial>
</link>

<joint name="base_link_to_kinect_link" type="fixed">
    <parent link="base_link"/>
    <child link="kinect_link"/>
    <origin rpy="0 0 0" xyz="0.5 0 0.19155"/><!--0.4-->
  </joint>


</robot>
